<sdf version='1.6'>
  <world name='default'>
    <light name='sun' type='directional'>
      <cast_shadows>1</cast_shadows>
      <pose frame=''>0 0 10 0 -0 0</pose>
      <diffuse>0.8 0.8 0.8 1</diffuse>
      <specular>0.1 0.1 0.1 1</specular>
      <attenuation>
        <range>1000</range>
        <constant>0.9</constant>
        <linear>0.01</linear>
        <quadratic>0.001</quadratic>
      </attenuation>
      <direction>-0.5 0.5 -1</direction>
    </light>
    <model name='ground_plane'>
      <static>1</static>
      <link name='link'>
        <collision name='collision'>
          <geometry>
            <plane>
              <normal>0 0 1</normal>
              <size>100 100</size>
            </plane>
          </geometry>
          <surface>
            <friction>
              <ode>
                <mu>100</mu>
                <mu2>50</mu2>
              </ode>
              <torsional>
                <ode/>
              </torsional>
            </friction>
            <contact>
              <ode/>
            </contact>
            <bounce/>
          </surface>
          <max_contacts>10</max_contacts>
        </collision>
        <visual name='visual'>
          <cast_shadows>0</cast_shadows>
          <geometry>
            <plane>
              <normal>0 0 1</normal>
              <size>100 100</size>
            </plane>
          </geometry>
          <material>
            <script>
              <uri>file://media/materials/scripts/gazebo.material</uri>
              <name>Gazebo/Grey</name>
            </script>
          </material>
        </visual>
        <self_collide>0</self_collide>
        <kinematic>0</kinematic>
        <gravity>1</gravity>
      </link>
    </model>
    <gravity>0 0 -9.8</gravity>
    <magnetic_field>6e-06 2.3e-05 -4.2e-05</magnetic_field>
    <atmosphere type='adiabatic'/>
    <physics name='default_physics' default='0' type='ode'>
      <max_step_size>0.001</max_step_size>
      <real_time_factor>1</real_time_factor>
      <real_time_update_rate>1000</real_time_update_rate>
    </physics>
    <scene>
      <ambient>0.4 0.4 0.4 1</ambient>
      <background>0.7 0.7 0.7 1</background>
      <shadows>1</shadows>
    </scene>
    <spherical_coordinates>
      <surface_model>EARTH_WGS84</surface_model>
      <latitude_deg>0</latitude_deg>
      <longitude_deg>0</longitude_deg>
      <elevation>0</elevation>
      <heading_deg>0</heading_deg>
    </spherical_coordinates>
    <model name='fetch'>
      <link name='base_link'>
        <pose frame=''>0 0 0 0 -0 0</pose>
        <inertial>
          <pose frame=''>-0.028329 0.000913 0.103558 0 -0 0</pose>
          <mass>83.4172</mass>
          <inertia>
            <ixx>6.20776</ixx>
            <ixy>0.0213393</ixy>
            <ixz>1.10946</ixz>
            <iyy>6.49062</iyy>
            <iyz>-0.0326202</iyz>
            <izz>1.3596</izz>
          </inertia>
        </inertial>
        <collision name='base_link_collision'>
          <pose frame=''>0 0 0 0 -0 0</pose>
          <geometry>
            <mesh>
              <scale>1 1 1</scale>
              <uri>/home/ozymandias/smoothiebot_ws/src/fetch_ros/fetch_description/meshes/base_link_collision.STL</uri>
            </mesh>
          </geometry>
          <surface>
            <contact>
              <ode>
                <kp>1e+08</kp>
                <kd>10</kd>
                <max_vel>10</max_vel>
                <min_depth>0.0005</min_depth>
              </ode>
            </contact>
            <friction>
              <ode>
                <mu>0.1</mu>
                <mu2>0.1</mu2>
                <fdir1>1 0 0</fdir1>
              </ode>
              <torsional>
                <ode/>
              </torsional>
            </friction>
            <bounce/>
          </surface>
          <max_contacts>10</max_contacts>
        </collision>
        <collision name='base_link_fixed_joint_lump__estop_link_collision_1'>
          <pose frame=''>-0.12465 0.23892 0.31127 1.5708 -0 0</pose>
          <geometry>
            <mesh>
              <scale>1 1 1</scale>
              <uri>/home/ozymandias/smoothiebot_ws/src/fetch_ros/fetch_description/meshes/estop_link.STL</uri>
            </mesh>
          </geometry>
          <surface>
            <contact>
              <ode/>
            </contact>
            <friction>
              <ode/>
              <torsional>
                <ode/>
              </torsional>
            </friction>
            <bounce/>
          </surface>
          <max_contacts>10</max_contacts>
        </collision>
        <collision name='base_link_fixed_joint_lump__laser_link_collision_2'>
          <pose frame=''>0.235 0 0.2878 -3.14159 -0 0</pose>
          <geometry>
            <mesh>
              <scale>1 1 1</scale>
              <uri>/home/ozymandias/smoothiebot_ws/src/fetch_ros/fetch_description/meshes/laser_link.STL</uri>
            </mesh>
          </geometry>
          <surface>
            <contact>
              <ode/>
            </contact>
            <friction>
              <ode/>
              <torsional>
                <ode/>
              </torsional>
            </friction>
            <bounce/>
          </surface>
          <max_contacts>10</max_contacts>
        </collision>
        <collision name='base_link_fixed_joint_lump__torso_fixed_link_collision_3'>
          <pose frame=''>-0.086875 0 0.377425 0 -0 0</pose>
          <geometry>
            <mesh>
              <scale>1 1 1</scale>
              <uri>/home/ozymandias/smoothiebot_ws/src/fetch_ros/fetch_description/meshes/torso_fixed_link.STL</uri>
            </mesh>
          </geometry>
          <max_contacts>10</max_contacts>
          <surface>
            <contact>
              <ode/>
            </contact>
            <bounce/>
            <friction>
              <torsional>
                <ode/>
              </torsional>
              <ode/>
            </friction>
          </surface>
        </collision>
        <visual name='base_link_visual'>
          <pose frame=''>0 0 0 0 -0 0</pose>
          <geometry>
            <mesh>
              <scale>1 1 1</scale>
              <uri>/home/ozymandias/smoothiebot_ws/src/fetch_ros/fetch_description/meshes/base_link.dae</uri>
            </mesh>
          </geometry>
          <material>
            <script>
              <uri>__default__</uri>
              <name>__default__</name>
            </script>
          </material>
        </visual>
        <visual name='base_link_fixed_joint_lump__estop_link_visual_1'>
          <pose frame=''>-0.12465 0.23892 0.31127 1.5708 -0 0</pose>
          <geometry>
            <mesh>
              <scale>1 1 1</scale>
              <uri>/home/ozymandias/smoothiebot_ws/src/fetch_ros/fetch_description/meshes/estop_link.STL</uri>
            </mesh>
          </geometry>
          <material>
            <script>
              <name>Gazebo/Red</name>
              <uri>file://media/materials/scripts/gazebo.material</uri>
            </script>
          </material>
        </visual>
        <visual name='base_link_fixed_joint_lump__laser_link_visual_2'>
          <pose frame=''>0.235 0 0.2878 -3.14159 -0 0</pose>
          <geometry>
            <mesh>
              <scale>1 1 1</scale>
              <uri>/home/ozymandias/smoothiebot_ws/src/fetch_ros/fetch_description/meshes/laser_link.STL</uri>
            </mesh>
          </geometry>
          <material>
            <script>
              <uri>__default__</uri>
              <name>__default__</name>
            </script>
          </material>
        </visual>
        <visual name='base_link_fixed_joint_lump__torso_fixed_link_visual_3'>
          <pose frame=''>-0.086875 0 0.377425 0 -0 0</pose>
          <geometry>
            <mesh>
              <scale>1 1 1</scale>
              <uri>/home/ozymandias/smoothiebot_ws/src/fetch_ros/fetch_description/meshes/torso_fixed_link.dae</uri>
            </mesh>
          </geometry>
        </visual>
        <velocity_decay/>
        <velocity_decay/>
        <gravity>1</gravity>
        <velocity_decay/>
        <self_collide>0</self_collide>
        <sensor name='base_laser' type='ray'>
          <visualize>0</visualize>
          <update_rate>15</update_rate>
          <ray>
            <scan>
              <horizontal>
                <samples>662</samples>
                <resolution>1</resolution>
                <min_angle>-1.91986</min_angle>
                <max_angle>1.91986</max_angle>
              </horizontal>
              <vertical>
                <samples>1</samples>
                <min_angle>0</min_angle>
                <max_angle>0</max_angle>
              </vertical>
            </scan>
            <range>
              <min>0.05</min>
              <max>25</max>
              <resolution>0.01</resolution>
            </range>
            <noise>
              <type>gaussian</type>
              <mean>0</mean>
              <stddev>0.02</stddev>
            </noise>
          </ray>
          <plugin name='gazebo_ros_base_hokuyo_controller' filename='libgazebo_ros_laser.so'>
            <topicName>/base_scan</topicName>
            <frameName>laser_link</frameName>
            <robotNamespace>/</robotNamespace>
          </plugin>
          <pose frame=''>0.235 0 0.2878 -3.14159 -0 0</pose>
        </sensor>
        <kinematic>0</kinematic>
      </link>
      <link name='l_wheel_link'>
        <pose frame=''>0.001291 0.18738 0.055325 0 -0 0</pose>
        <inertial>
          <pose frame=''>0 0 0 0 -0 0</pose>
          <mass>4.3542</mass>
          <inertia>
            <ixx>0.0045</ixx>
            <ixy>0</ixy>
            <ixz>0</ixz>
            <iyy>0.005</iyy>
            <iyz>0</iyz>
            <izz>0.0045</izz>
          </inertia>
        </inertial>
        <collision name='l_wheel_link_collision'>
          <pose frame=''>0 0 0 0 -0 0</pose>
          <geometry>
            <mesh>
              <scale>1 1 1</scale>
              <uri>/home/ozymandias/smoothiebot_ws/src/fetch_ros/fetch_description/meshes/l_wheel_link_collision.STL</uri>
            </mesh>
          </geometry>
          <surface>
            <contact>
              <ode>
                <kp>500000</kp>
                <kd>10</kd>
                <max_vel>1</max_vel>
                <min_depth>0.003</min_depth>
              </ode>
            </contact>
            <friction>
              <ode>
                <mu>10</mu>
                <mu2>10</mu2>
                <fdir1>1 0 0</fdir1>
              </ode>
              <torsional>
                <ode/>
              </torsional>
            </friction>
            <bounce/>
          </surface>
          <max_contacts>10</max_contacts>
        </collision>
        <visual name='l_wheel_link_visual'>
          <pose frame=''>0 0 0 0 -0 0</pose>
          <geometry>
            <mesh>
              <scale>1 1 1</scale>
              <uri>/home/ozymandias/smoothiebot_ws/src/fetch_ros/fetch_description/meshes/l_wheel_link.STL</uri>
            </mesh>
          </geometry>
          <material>
            <script>
              <name>Gazebo/Black</name>
              <uri>file://media/materials/scripts/gazebo.material</uri>
            </script>
          </material>
        </visual>
        <gravity>1</gravity>
        <velocity_decay/>
        <self_collide>0</self_collide>
        <kinematic>0</kinematic>
      </link>
      <joint name='l_wheel_joint' type='revolute'>
        <child>l_wheel_link</child>
        <parent>base_link</parent>
        <axis>
          <xyz>0 1 0</xyz>
          <limit>
            <lower>-1e+16</lower>
            <upper>1e+16</upper>
          </limit>
          <dynamics>
            <spring_reference>0</spring_reference>
            <spring_stiffness>0</spring_stiffness>
          </dynamics>
          <use_parent_model_frame>1</use_parent_model_frame>
        </axis>
        <physics>
          <ode>
            <implicit_spring_damper>1</implicit_spring_damper>
            <cfm_damping>1</cfm_damping>
            <limit>
              <cfm>0</cfm>
              <erp>0.2</erp>
            </limit>
          </ode>
        </physics>
      </joint>
      <link name='r_wheel_link'>
        <pose frame=''>0.001291 -0.18738 0.055325 0 -0 0</pose>
        <inertial>
          <pose frame=''>0 0 0 0 -0 0</pose>
          <mass>4.3542</mass>
          <inertia>
            <ixx>0.0045</ixx>
            <ixy>0</ixy>
            <ixz>0</ixz>
            <iyy>0.005</iyy>
            <iyz>0</iyz>
            <izz>0.0045</izz>
          </inertia>
        </inertial>
        <collision name='r_wheel_link_collision'>
          <pose frame=''>0 0 0 0 -0 0</pose>
          <geometry>
            <mesh>
              <scale>1 1 1</scale>
              <uri>/home/ozymandias/smoothiebot_ws/src/fetch_ros/fetch_description/meshes/r_wheel_link_collision.STL</uri>
            </mesh>
          </geometry>
          <surface>
            <contact>
              <ode>
                <kp>500000</kp>
                <kd>10</kd>
                <max_vel>1</max_vel>
                <min_depth>0.003</min_depth>
              </ode>
            </contact>
            <friction>
              <ode>
                <mu>10</mu>
                <mu2>10</mu2>
                <fdir1>1 0 0</fdir1>
              </ode>
              <torsional>
                <ode/>
              </torsional>
            </friction>
            <bounce/>
          </surface>
          <max_contacts>10</max_contacts>
        </collision>
        <visual name='r_wheel_link_visual'>
          <pose frame=''>0 0 0 0 -0 0</pose>
          <geometry>
            <mesh>
              <scale>1 1 1</scale>
              <uri>/home/ozymandias/smoothiebot_ws/src/fetch_ros/fetch_description/meshes/r_wheel_link.STL</uri>
            </mesh>
          </geometry>
          <material>
            <script>
              <name>Gazebo/Black</name>
              <uri>file://media/materials/scripts/gazebo.material</uri>
            </script>
          </material>
        </visual>
        <gravity>1</gravity>
        <velocity_decay/>
        <self_collide>0</self_collide>
        <kinematic>0</kinematic>
      </link>
      <joint name='r_wheel_joint' type='revolute'>
        <child>r_wheel_link</child>
        <parent>base_link</parent>
        <axis>
          <xyz>0 1 0</xyz>
          <limit>
            <lower>-1e+16</lower>
            <upper>1e+16</upper>
          </limit>
          <dynamics>
            <spring_reference>0</spring_reference>
            <spring_stiffness>0</spring_stiffness>
          </dynamics>
          <use_parent_model_frame>1</use_parent_model_frame>
        </axis>
        <physics>
          <ode>
            <implicit_spring_damper>1</implicit_spring_damper>
            <cfm_damping>1</cfm_damping>
            <limit>
              <cfm>0</cfm>
              <erp>0.2</erp>
            </limit>
          </ode>
        </physics>
      </joint>
      <link name='torso_lift_link'>
        <pose frame=''>-0.086875 0 0.37743 0 -0 0</pose>
        <inertial>
          <pose frame=''>-0.000984 -0.000886 0.286874 0 -0 0</pose>
          <mass>10.949</mass>
          <inertia>
            <ixx>0.36931</ixx>
            <ixy>-3.0664e-06</ixy>
            <ixz>-0.0147406</ixz>
            <iyy>0.367812</iyy>
            <iyz>-0.000535712</iyz>
            <izz>0.0971639</izz>
          </inertia>
        </inertial>
        <collision name='torso_lift_link_collision'>
          <pose frame=''>0 0 0 0 -0 0</pose>
          <geometry>
            <mesh>
              <scale>1 1 1</scale>
              <uri>/home/ozymandias/smoothiebot_ws/src/fetch_ros/fetch_description/meshes/torso_lift_link_collision.STL</uri>
            </mesh>
          </geometry>
          <max_contacts>10</max_contacts>
          <surface>
            <contact>
              <ode/>
            </contact>
            <bounce/>
            <friction>
              <torsional>
                <ode/>
              </torsional>
              <ode/>
            </friction>
          </surface>
        </collision>
        <collision name='torso_lift_link_fixed_joint_lump__bellows_link2_collision_1'>
          <pose frame=''>0 0 0 0 -0 0</pose>
          <geometry>
            <mesh>
              <scale>1 1 1</scale>
              <uri>/home/ozymandias/smoothiebot_ws/src/fetch_ros/fetch_description/meshes/bellows_link_collision.STL</uri>
            </mesh>
          </geometry>
          <surface>
            <contact>
              <ode/>
            </contact>
            <friction>
              <ode/>
              <torsional>
                <ode/>
              </torsional>
            </friction>
            <bounce/>
          </surface>
          <max_contacts>10</max_contacts>
        </collision>
        <visual name='torso_lift_link_visual'>
          <pose frame=''>0 0 0 0 -0 0</pose>
          <geometry>
            <mesh>
              <scale>1 1 1</scale>
              <uri>/home/ozymandias/smoothiebot_ws/src/fetch_ros/fetch_description/meshes/torso_lift_link.dae</uri>
            </mesh>
          </geometry>
        </visual>
        <visual name='torso_lift_link_fixed_joint_lump__bellows_link2_visual_1'>
          <pose frame=''>0 0 0 0 -0 0</pose>
          <geometry>
            <mesh>
              <scale>1 1 1</scale>
              <uri>/home/ozymandias/smoothiebot_ws/src/fetch_ros/fetch_description/meshes/bellows_link.STL</uri>
            </mesh>
          </geometry>
          <material>
            <script>
              <name>Gazebo/Black</name>
              <uri>file://media/materials/scripts/gazebo.material</uri>
            </script>
          </material>
        </visual>
        <gravity>1</gravity>
        <velocity_decay/>
        <self_collide>0</self_collide>
        <kinematic>0</kinematic>
      </link>
      <joint name='torso_lift_joint' type='prismatic'>
        <child>torso_lift_link</child>
        <parent>base_link</parent>
        <axis>
          <xyz>0 0 1</xyz>
          <limit>
            <lower>0</lower>
            <upper>0.38615</upper>
            <effort>450</effort>
            <velocity>0.1</velocity>
          </limit>
          <dynamics>
            <damping>100</damping>
            <friction>0</friction>
            <spring_reference>0</spring_reference>
            <spring_stiffness>0</spring_stiffness>
          </dynamics>
          <use_parent_model_frame>1</use_parent_model_frame>
        </axis>
      </joint>
      <link name='bellows_link'>
        <pose frame=''>-0.086875 0 0.37743 0 -0 0</pose>
        <inertial>
          <pose frame=''>0.019132 -0 -0.134862 0 -0 0</pose>
          <mass>0.169374</mass>
          <inertia>
            <ixx>0.00331159</ixx>
            <ixy>-8.9231e-18</ixy>
            <ixz>-5.38622e-08</ixz>
            <iyy>0.00174447</iyy>
            <iyz>-8.06965e-17</iyz>
            <izz>0.00169418</izz>
          </inertia>
        </inertial>
        <collision name='bellows_link_collision'>
          <pose frame=''>0 0 0 0 -0 0</pose>
          <geometry>
            <mesh>
              <scale>1 1 1</scale>
              <uri>/home/ozymandias/smoothiebot_ws/src/fetch_ros/fetch_description/meshes/bellows_link_collision.STL</uri>
            </mesh>
          </geometry>
          <surface>
            <contact>
              <ode/>
            </contact>
            <friction>
              <ode/>
              <torsional>
                <ode/>
              </torsional>
            </friction>
            <bounce/>
          </surface>
          <max_contacts>10</max_contacts>
        </collision>
        <visual name='bellows_link_visual'>
          <pose frame=''>0 0 0 0 -0 0</pose>
          <geometry>
            <mesh>
              <scale>1 1 1</scale>
              <uri>/home/ozymandias/smoothiebot_ws/src/fetch_ros/fetch_description/meshes/bellows_link.STL</uri>
            </mesh>
          </geometry>
          <material>
            <script>
              <name>Gazebo/Black</name>
              <uri>file://media/materials/scripts/gazebo.material</uri>
            </script>
          </material>
        </visual>
        <gravity>1</gravity>
        <velocity_decay/>
        <self_collide>0</self_collide>
        <kinematic>0</kinematic>
      </link>
      <joint name='bellows_joint' type='prismatic'>
        <child>bellows_link</child>
        <parent>torso_lift_link</parent>
        <axis>
          <xyz>0 -0 -1</xyz>
          <limit>
            <lower>0</lower>
            <upper>0.4</upper>
            <effort>5</effort>
            <velocity>0.1</velocity>
          </limit>
          <dynamics>
            <spring_reference>0</spring_reference>
            <spring_stiffness>0</spring_stiffness>
          </dynamics>
          <use_parent_model_frame>1</use_parent_model_frame>
        </axis>
      </joint>
      <link name='head_pan_link'>
        <pose frame=''>-0.03375 0 0.980431 0 -0 0</pose>
        <inertial>
          <pose frame=''>0.0321 0.0161 0.039 0 -0 0</pose>
          <mass>2.2556</mass>
          <inertia>
            <ixx>0.0129</ixx>
            <ixy>0.0002</ixy>
            <ixz>0.0007</ixz>
            <iyy>0.0095</iyy>
            <iyz>-0</iyz>
            <izz>0.0184</izz>
          </inertia>
        </inertial>
        <collision name='head_pan_link_collision'>
          <pose frame=''>0 0 0 0 -0 0</pose>
          <geometry>
            <mesh>
              <scale>1 1 1</scale>
              <uri>/home/ozymandias/smoothiebot_ws/src/fetch_ros/fetch_description/meshes/head_pan_link_collision.STL</uri>
            </mesh>
          </geometry>
          <max_contacts>10</max_contacts>
          <surface>
            <contact>
              <ode/>
            </contact>
            <bounce/>
            <friction>
              <torsional>
                <ode/>
              </torsional>
              <ode/>
            </friction>
          </surface>
        </collision>
        <visual name='head_pan_link_visual'>
          <pose frame=''>0 0 0 0 -0 0</pose>
          <geometry>
            <mesh>
              <scale>1 1 1</scale>
              <uri>/home/ozymandias/smoothiebot_ws/src/fetch_ros/fetch_description/meshes/head_pan_link.dae</uri>
            </mesh>
          </geometry>
        </visual>
        <self_collide>0</self_collide>
        <kinematic>0</kinematic>
        <gravity>1</gravity>
      </link>
      <joint name='head_pan_joint' type='revolute'>
        <child>head_pan_link</child>
        <parent>torso_lift_link</parent>
        <axis>
          <xyz>0 0 1</xyz>
          <limit>
            <lower>-1.57</lower>
            <upper>1.57</upper>
            <effort>0.32</effort>
            <velocity>1.57</velocity>
          </limit>
          <dynamics>
            <spring_reference>0</spring_reference>
            <spring_stiffness>0</spring_stiffness>
          </dynamics>
          <use_parent_model_frame>1</use_parent_model_frame>
        </axis>
      </joint>
      <link name='head_tilt_link'>
        <pose frame=''>0.10878 0 1.03843 0 -0 0</pose>
        <inertial>
          <pose frame=''>0.0081 0.0025 0.0113 0 -0 0</pose>
          <mass>0.9087</mass>
          <inertia>
            <ixx>0.0061</ixx>
            <ixy>-0</ixy>
            <ixz>0.0002</ixz>
            <iyy>0.0014</iyy>
            <iyz>-0.0001</iyz>
            <izz>0.0061</izz>
          </inertia>
        </inertial>
        <collision name='head_tilt_link_collision'>
          <pose frame=''>0 0 0 0 -0 0</pose>
          <geometry>
            <mesh>
              <scale>1 1 1</scale>
              <uri>/home/ozymandias/smoothiebot_ws/src/fetch_ros/fetch_description/meshes/head_tilt_link_collision.STL</uri>
            </mesh>
          </geometry>
          <max_contacts>10</max_contacts>
          <surface>
            <contact>
              <ode/>
            </contact>
            <bounce/>
            <friction>
              <torsional>
                <ode/>
              </torsional>
              <ode/>
            </friction>
          </surface>
        </collision>
        <visual name='head_tilt_link_visual'>
          <pose frame=''>0 0 0 0 -0 0</pose>
          <geometry>
            <mesh>
              <scale>1 1 1</scale>
              <uri>/home/ozymandias/smoothiebot_ws/src/fetch_ros/fetch_description/meshes/head_tilt_link.dae</uri>
            </mesh>
          </geometry>
        </visual>
        <gravity>1</gravity>
        <velocity_decay/>
        <self_collide>0</self_collide>
        <sensor name='camera' type='depth'>
          <always_on>1</always_on>
          <update_rate>15</update_rate>
          <camera name='__default__'>
            <horizontal_fov>1.0472</horizontal_fov>
            <image>
              <format>B8G8R8</format>
              <width>640</width>
              <height>480</height>
            </image>
            <clip>
              <near>0.05</near>
              <far>50</far>
            </clip>
          </camera>
          <plugin name='head_camera_controller' filename='libgazebo_ros_openni_kinect.so'>
            <baseline>0.1</baseline>
            <alwaysOn>true</alwaysOn>
            <updateRate>15.0</updateRate>
            <cameraName>head_camera</cameraName>
            <imageTopicName>/head_camera/rgb/image_raw</imageTopicName>
            <cameraInfoTopicName>/head_camera/rgb/camera_info</cameraInfoTopicName>
            <depthImageTopicName>/head_camera/depth_registered/image_raw</depthImageTopicName>
            <depthImageCameraInfoTopicName>/head_camera/depth_registered/camera_info</depthImageCameraInfoTopicName>
            <pointCloudTopicName>/head_camera/depth_registered/points</pointCloudTopicName>
            <frameName>head_camera_rgb_optical_frame</frameName>
            <pointCloudCutoff>0.35</pointCloudCutoff>
            <pointCloudCutoffMax>4.5</pointCloudCutoffMax>
            <CxPrime>0</CxPrime>
            <Cx>0</Cx>
            <Cy>0</Cy>
            <focalLength>0</focalLength>
            <hackBaseline>0</hackBaseline>
            <robotNamespace>/</robotNamespace>
          </plugin>
          <pose frame=''>0.055 0.02 0.0225 0 -0 0</pose>
        </sensor>
        <kinematic>0</kinematic>
      </link>
      <joint name='head_tilt_joint' type='revolute'>
        <child>head_tilt_link</child>
        <parent>head_pan_link</parent>
        <axis>
          <xyz>0 1 0</xyz>
          <limit>
            <lower>-0.76</lower>
            <upper>1.45</upper>
            <effort>0.68</effort>
            <velocity>1.57</velocity>
          </limit>
          <dynamics>
            <spring_reference>0</spring_reference>
            <spring_stiffness>0</spring_stiffness>
          </dynamics>
          <use_parent_model_frame>1</use_parent_model_frame>
        </axis>
      </joint>
      <link name='shoulder_pan_link'>
        <pose frame=''>0.03265 0 0.72601 0 -0 0</pose>
        <inertial>
          <pose frame=''>0.0927 -0.0056 0.0564 0 -0 0</pose>
          <mass>2.5587</mass>
          <inertia>
            <ixx>0.0043</ixx>
            <ixy>-0.0001</ixy>
            <ixz>0.001</ixz>
            <iyy>0.0087</iyy>
            <iyz>-0.0001</iyz>
            <izz>0.0087</izz>
          </inertia>
        </inertial>
        <collision name='shoulder_pan_link_collision'>
          <pose frame=''>0 0 0 0 -0 0</pose>
          <geometry>
            <mesh>
              <scale>1 1 1</scale>
              <uri>/home/ozymandias/smoothiebot_ws/src/fetch_ros/fetch_description/meshes/shoulder_pan_link_collision.STL</uri>
            </mesh>
          </geometry>
          <max_contacts>10</max_contacts>
          <surface>
            <contact>
              <ode/>
            </contact>
            <bounce/>
            <friction>
              <torsional>
                <ode/>
              </torsional>
              <ode/>
            </friction>
          </surface>
        </collision>
        <visual name='shoulder_pan_link_visual'>
          <pose frame=''>0 0 0 0 -0 0</pose>
          <geometry>
            <mesh>
              <scale>1 1 1</scale>
              <uri>/home/ozymandias/smoothiebot_ws/src/fetch_ros/fetch_description/meshes/shoulder_pan_link.dae</uri>
            </mesh>
          </geometry>
        </visual>
        <self_collide>0</self_collide>
        <kinematic>0</kinematic>
        <gravity>1</gravity>
      </link>
      <joint name='shoulder_pan_joint' type='revolute'>
        <child>shoulder_pan_link</child>
        <parent>torso_lift_link</parent>
        <axis>
          <xyz>0 0 1</xyz>
          <limit>
            <lower>-1.6056</lower>
            <upper>1.6056</upper>
            <effort>33.82</effort>
            <velocity>1.256</velocity>
          </limit>
          <dynamics>
            <damping>1</damping>
            <friction>0</friction>
            <spring_reference>0</spring_reference>
            <spring_stiffness>0</spring_stiffness>
          </dynamics>
          <use_parent_model_frame>1</use_parent_model_frame>
        </axis>
      </joint>
      <link name='shoulder_lift_link'>
        <pose frame=''>0.14965 0 0.78601 0 -0 0</pose>
        <inertial>
          <pose frame=''>0.1432 0.0072 -0.0001 0 -0 0</pose>
          <mass>2.6615</mass>
          <inertia>
            <ixx>0.0028</ixx>
            <ixy>-0.0021</ixy>
            <ixz>-0</ixz>
            <iyy>0.0111</iyy>
            <iyz>-0</iyz>
            <izz>0.0112</izz>
          </inertia>
        </inertial>
        <collision name='shoulder_lift_link_collision'>
          <pose frame=''>0 0 0 0 -0 0</pose>
          <geometry>
            <mesh>
              <scale>1 1 1</scale>
              <uri>/home/ozymandias/smoothiebot_ws/src/fetch_ros/fetch_description/meshes/shoulder_lift_link_collision.STL</uri>
            </mesh>
          </geometry>
          <max_contacts>10</max_contacts>
          <surface>
            <contact>
              <ode/>
            </contact>
            <bounce/>
            <friction>
              <torsional>
                <ode/>
              </torsional>
              <ode/>
            </friction>
          </surface>
        </collision>
        <visual name='shoulder_lift_link_visual'>
          <pose frame=''>0 0 0 0 -0 0</pose>
          <geometry>
            <mesh>
              <scale>1 1 1</scale>
              <uri>/home/ozymandias/smoothiebot_ws/src/fetch_ros/fetch_description/meshes/shoulder_lift_link.dae</uri>
            </mesh>
          </geometry>
        </visual>
        <self_collide>0</self_collide>
        <kinematic>0</kinematic>
        <gravity>1</gravity>
      </link>
      <joint name='shoulder_lift_joint' type='revolute'>
        <child>shoulder_lift_link</child>
        <parent>shoulder_pan_link</parent>
        <axis>
          <xyz>0 1 0</xyz>
          <limit>
            <lower>-1.221</lower>
            <upper>1.518</upper>
            <effort>131.76</effort>
            <velocity>1.454</velocity>
          </limit>
          <dynamics>
            <damping>1</damping>
            <friction>0</friction>
            <spring_reference>0</spring_reference>
            <spring_stiffness>0</spring_stiffness>
          </dynamics>
          <use_parent_model_frame>1</use_parent_model_frame>
        </axis>
      </joint>
      <link name='upperarm_roll_link'>
        <pose frame=''>0.36865 0 0.78601 0 -0 0</pose>
        <inertial>
          <pose frame=''>0.1165 0.0014 0 0 -0 0</pose>
          <mass>2.3311</mass>
          <inertia>
            <ixx>0.0019</ixx>
            <ixy>-0.0001</ixy>
            <ixz>0</ixz>
            <iyy>0.0045</iyy>
            <iyz>0</iyz>
            <izz>0.0047</izz>
          </inertia>
        </inertial>
        <collision name='upperarm_roll_link_collision'>
          <pose frame=''>0 0 0 0 -0 0</pose>
          <geometry>
            <mesh>
              <scale>1 1 1</scale>
              <uri>/home/ozymandias/smoothiebot_ws/src/fetch_ros/fetch_description/meshes/upperarm_roll_link_collision.STL</uri>
            </mesh>
          </geometry>
          <max_contacts>10</max_contacts>
          <surface>
            <contact>
              <ode/>
            </contact>
            <bounce/>
            <friction>
              <torsional>
                <ode/>
              </torsional>
              <ode/>
            </friction>
          </surface>
        </collision>
        <visual name='upperarm_roll_link_visual'>
          <pose frame=''>0 0 0 0 -0 0</pose>
          <geometry>
            <mesh>
              <scale>1 1 1</scale>
              <uri>/home/ozymandias/smoothiebot_ws/src/fetch_ros/fetch_description/meshes/upperarm_roll_link.dae</uri>
            </mesh>
          </geometry>
        </visual>
        <self_collide>0</self_collide>
        <kinematic>0</kinematic>
        <gravity>1</gravity>
      </link>
      <joint name='upperarm_roll_joint' type='revolute'>
        <child>upperarm_roll_link</child>
        <parent>shoulder_lift_link</parent>
        <axis>
          <xyz>1 0 0</xyz>
          <limit>
            <lower>-1e+16</lower>
            <upper>1e+16</upper>
          </limit>
          <dynamics>
            <damping>5</damping>
            <friction>0</friction>
            <spring_reference>0</spring_reference>
            <spring_stiffness>0</spring_stiffness>
          </dynamics>
          <use_parent_model_frame>1</use_parent_model_frame>
        </axis>
      </joint>
      <link name='elbow_flex_link'>
        <pose frame=''>0.50165 0 0.78601 0 -0 0</pose>
        <inertial>
          <pose frame=''>0.1279 0.0073 0 0 -0 0</pose>
          <mass>2.1299</mass>
          <inertia>
            <ixx>0.0024</ixx>
            <ixy>-0.0016</ixy>
            <ixz>0</ixz>
            <iyy>0.0082</iyy>
            <iyz>-0</iyz>
            <izz>0.0084</izz>
          </inertia>
        </inertial>
        <collision name='elbow_flex_link_collision'>
          <pose frame=''>0 0 0 0 -0 0</pose>
          <geometry>
            <mesh>
              <scale>1 1 1</scale>
              <uri>/home/ozymandias/smoothiebot_ws/src/fetch_ros/fetch_description/meshes/elbow_flex_link_collision.STL</uri>
            </mesh>
          </geometry>
          <max_contacts>10</max_contacts>
          <surface>
            <contact>
              <ode/>
            </contact>
            <bounce/>
            <friction>
              <torsional>
                <ode/>
              </torsional>
              <ode/>
            </friction>
          </surface>
        </collision>
        <visual name='elbow_flex_link_visual'>
          <pose frame=''>0 0 0 0 -0 0</pose>
          <geometry>
            <mesh>
              <scale>1 1 1</scale>
              <uri>/home/ozymandias/smoothiebot_ws/src/fetch_ros/fetch_description/meshes/elbow_flex_link.dae</uri>
            </mesh>
          </geometry>
        </visual>
        <self_collide>0</self_collide>
        <kinematic>0</kinematic>
        <gravity>1</gravity>
      </link>
      <joint name='elbow_flex_joint' type='revolute'>
        <child>elbow_flex_link</child>
        <parent>upperarm_roll_link</parent>
        <axis>
          <xyz>0 1 0</xyz>
          <limit>
            <lower>-2.251</lower>
            <upper>2.251</upper>
            <effort>66.18</effort>
            <velocity>1.521</velocity>
          </limit>
          <dynamics>
            <damping>1</damping>
            <friction>0</friction>
            <spring_reference>0</spring_reference>
            <spring_stiffness>0</spring_stiffness>
          </dynamics>
          <use_parent_model_frame>1</use_parent_model_frame>
        </axis>
      </joint>
      <link name='forearm_roll_link'>
        <pose frame=''>0.69865 0 0.78601 0 -0 0</pose>
        <inertial>
          <pose frame=''>0.1097 -0.0266 0 0 -0 0</pose>
          <mass>1.6563</mass>
          <inertia>
            <ixx>0.0016</ixx>
            <ixy>-0.0003</ixy>
            <ixz>0</ixz>
            <iyy>0.003</iyy>
            <iyz>-0</iyz>
            <izz>0.0035</izz>
          </inertia>
        </inertial>
        <collision name='forearm_roll_link_collision'>
          <pose frame=''>0 0 0 0 -0 0</pose>
          <geometry>
            <mesh>
              <scale>1 1 1</scale>
              <uri>/home/ozymandias/smoothiebot_ws/src/fetch_ros/fetch_description/meshes/forearm_roll_link_collision.STL</uri>
            </mesh>
          </geometry>
          <max_contacts>10</max_contacts>
          <surface>
            <contact>
              <ode/>
            </contact>
            <bounce/>
            <friction>
              <torsional>
                <ode/>
              </torsional>
              <ode/>
            </friction>
          </surface>
        </collision>
        <visual name='forearm_roll_link_visual'>
          <pose frame=''>0 0 0 0 -0 0</pose>
          <geometry>
            <mesh>
              <scale>1 1 1</scale>
              <uri>/home/ozymandias/smoothiebot_ws/src/fetch_ros/fetch_description/meshes/forearm_roll_link.dae</uri>
            </mesh>
          </geometry>
        </visual>
        <self_collide>0</self_collide>
        <kinematic>0</kinematic>
        <gravity>1</gravity>
      </link>
      <joint name='forearm_roll_joint' type='revolute'>
        <child>forearm_roll_link</child>
        <parent>elbow_flex_link</parent>
        <axis>
          <xyz>1 0 0</xyz>
          <limit>
            <lower>-1e+16</lower>
            <upper>1e+16</upper>
          </limit>
          <dynamics>
            <damping>5</damping>
            <friction>0</friction>
            <spring_reference>0</spring_reference>
            <spring_stiffness>0</spring_stiffness>
          </dynamics>
          <use_parent_model_frame>1</use_parent_model_frame>
        </axis>
        <physics>
          <ode>
            <implicit_spring_damper>1</implicit_spring_damper>
            <cfm_damping>1</cfm_damping>
            <limit>
              <cfm>0</cfm>
              <erp>0.2</erp>
            </limit>
          </ode>
        </physics>
      </joint>
      <link name='wrist_flex_link'>
        <pose frame=''>0.82315 0 0.78601 0 -0 0</pose>
        <inertial>
          <pose frame=''>0.0882 0.0009 -0.0001 0 -0 0</pose>
          <mass>1.725</mass>
          <inertia>
            <ixx>0.0018</ixx>
            <ixy>-0.0001</ixy>
            <ixz>-0</ixz>
            <iyy>0.0042</iyy>
            <iyz>0</iyz>
            <izz>0.0042</izz>
          </inertia>
        </inertial>
        <collision name='wrist_flex_link_collision'>
          <pose frame=''>0 0 0 0 -0 0</pose>
          <geometry>
            <mesh>
              <scale>1 1 1</scale>
              <uri>/home/ozymandias/smoothiebot_ws/src/fetch_ros/fetch_description/meshes/wrist_flex_link_collision.STL</uri>
            </mesh>
          </geometry>
          <max_contacts>10</max_contacts>
          <surface>
            <contact>
              <ode/>
            </contact>
            <bounce/>
            <friction>
              <torsional>
                <ode/>
              </torsional>
              <ode/>
            </friction>
          </surface>
        </collision>
        <visual name='wrist_flex_link_visual'>
          <pose frame=''>0 0 0 0 -0 0</pose>
          <geometry>
            <mesh>
              <scale>1 1 1</scale>
              <uri>/home/ozymandias/smoothiebot_ws/src/fetch_ros/fetch_description/meshes/wrist_flex_link.dae</uri>
            </mesh>
          </geometry>
        </visual>
        <self_collide>0</self_collide>
        <kinematic>0</kinematic>
        <gravity>1</gravity>
      </link>
      <joint name='wrist_flex_joint' type='revolute'>
        <child>wrist_flex_link</child>
        <parent>forearm_roll_link</parent>
        <axis>
          <xyz>0 1 0</xyz>
          <limit>
            <lower>-2.16</lower>
            <upper>2.16</upper>
            <effort>25.7</effort>
            <velocity>2.268</velocity>
          </limit>
          <dynamics>
            <damping>1</damping>
            <friction>0</friction>
            <spring_reference>0</spring_reference>
            <spring_stiffness>0</spring_stiffness>
          </dynamics>
          <use_parent_model_frame>1</use_parent_model_frame>
        </axis>
      </joint>
      <link name='wrist_roll_link'>
        <pose frame=''>0.96165 0 0.78601 0 -0 0</pose>
        <inertial>
          <pose frame=''>0.070966 -5.9e-05 -0.001577 0 -0 0</pose>
          <mass>1.6529</mass>
          <inertia>
            <ixx>0.00140031</ixx>
            <ixy>4.16123e-06</ixy>
            <ixz>1.24837e-05</ixz>
            <iyy>0.00255747</iyy>
            <iyz>-9.32314e-08</iyz>
            <izz>0.00305722</izz>
          </inertia>
        </inertial>
        <collision name='wrist_roll_link_collision'>
          <pose frame=''>0 0 0 0 -0 0</pose>
          <geometry>
            <mesh>
              <scale>1 1 1</scale>
              <uri>/home/ozymandias/smoothiebot_ws/src/fetch_ros/fetch_description/meshes/wrist_roll_link_collision.STL</uri>
            </mesh>
          </geometry>
          <max_contacts>10</max_contacts>
          <surface>
            <contact>
              <ode/>
            </contact>
            <bounce/>
            <friction>
              <torsional>
                <ode/>
              </torsional>
              <ode/>
            </friction>
          </surface>
        </collision>
        <collision name='wrist_roll_link_fixed_joint_lump__gripper_link_collision_1'>
          <pose frame=''>0.16645 0 0 0 -0 0</pose>
          <geometry>
            <mesh>
              <scale>1 1 1</scale>
              <uri>/home/ozymandias/smoothiebot_ws/src/fetch_ros/fetch_description/meshes/gripper_link.STL</uri>
            </mesh>
          </geometry>
          <max_contacts>10</max_contacts>
          <surface>
            <contact>
              <ode/>
            </contact>
            <bounce/>
            <friction>
              <torsional>
                <ode/>
              </torsional>
              <ode/>
            </friction>
          </surface>
        </collision>
        <visual name='wrist_roll_link_visual'>
          <pose frame=''>0 0 0 0 -0 0</pose>
          <geometry>
            <mesh>
              <scale>1 1 1</scale>
              <uri>/home/ozymandias/smoothiebot_ws/src/fetch_ros/fetch_description/meshes/wrist_roll_link.dae</uri>
            </mesh>
          </geometry>
        </visual>
        <visual name='wrist_roll_link_fixed_joint_lump__gripper_link_visual_1'>
          <pose frame=''>0.16645 0 0 0 -0 0</pose>
          <geometry>
            <mesh>
              <scale>1 1 1</scale>
              <uri>/home/ozymandias/smoothiebot_ws/src/fetch_ros/fetch_description/meshes/gripper_link.dae</uri>
            </mesh>
          </geometry>
        </visual>
        <self_collide>0</self_collide>
        <kinematic>0</kinematic>
        <gravity>1</gravity>
      </link>
      <joint name='wrist_roll_joint' type='revolute'>
        <child>wrist_roll_link</child>
        <parent>wrist_flex_link</parent>
        <axis>
          <xyz>1 0 0</xyz>
          <limit>
            <lower>-1e+16</lower>
            <upper>1e+16</upper>
          </limit>
          <dynamics>
            <damping>5</damping>
            <friction>0</friction>
            <spring_reference>0</spring_reference>
            <spring_stiffness>0</spring_stiffness>
          </dynamics>
          <use_parent_model_frame>1</use_parent_model_frame>
        </axis>
        <physics>
          <ode>
            <implicit_spring_damper>1</implicit_spring_damper>
            <cfm_damping>1</cfm_damping>
            <limit>
              <cfm>0</cfm>
              <erp>0.2</erp>
            </limit>
          </ode>
        </physics>
      </joint>
      <link name='l_gripper_finger_link'>
        <pose frame=''>1.1281 -0.015425 0.78601 0 -0 0</pose>
        <inertial>
          <pose frame=''>-0.01 0 0 0 -0 0</pose>
          <mass>0.0798</mass>
          <inertia>
            <ixx>0.002</ixx>
            <ixy>0</ixy>
            <ixz>0</ixz>
            <iyy>0</iyy>
            <iyz>0</iyz>
            <izz>0</izz>
          </inertia>
        </inertial>
        <collision name='l_gripper_finger_link_collision'>
          <pose frame=''>0 -0.101425 0 0 -0 0</pose>
          <geometry>
            <mesh>
              <scale>1 1 1</scale>
              <uri>/home/ozymandias/smoothiebot_ws/src/fetch_ros/fetch_description/meshes/l_gripper_finger_link.STL</uri>
            </mesh>
          </geometry>
          <surface>
            <contact>
              <ode>
                <kp>1e+06</kp>
                <kd>100</kd>
                <max_vel>1</max_vel>
                <min_depth>0.001</min_depth>
              </ode>
            </contact>
            <friction>
              <ode>
                <mu>30</mu>
                <mu2>30</mu2>
              </ode>
              <torsional>
                <ode/>
              </torsional>
            </friction>
            <bounce/>
          </surface>
          <max_contacts>10</max_contacts>
        </collision>
        <visual name='l_gripper_finger_link_visual'>
          <pose frame=''>0 -0.101425 0 0 -0 0</pose>
          <geometry>
            <mesh>
              <scale>1 1 1</scale>
              <uri>/home/ozymandias/smoothiebot_ws/src/fetch_ros/fetch_description/meshes/l_gripper_finger_link.STL</uri>
            </mesh>
          </geometry>
          <material>
            <script>
              <name>Gazebo/Grey</name>
              <uri>file://media/materials/scripts/gazebo.material</uri>
            </script>
          </material>
        </visual>
        <gravity>1</gravity>
        <velocity_decay/>
        <self_collide>0</self_collide>
        <kinematic>0</kinematic>
      </link>
      <joint name='l_gripper_finger_joint' type='prismatic'>
        <child>l_gripper_finger_link</child>
        <parent>wrist_roll_link</parent>
        <axis>
          <xyz>0 -1 0</xyz>
          <limit>
            <lower>0</lower>
            <upper>0.05</upper>
            <effort>60</effort>
            <velocity>0.05</velocity>
          </limit>
          <dynamics>
            <damping>100</damping>
            <friction>0</friction>
            <spring_reference>0</spring_reference>
            <spring_stiffness>0</spring_stiffness>
          </dynamics>
          <use_parent_model_frame>1</use_parent_model_frame>
        </axis>
      </joint>
      <link name='r_gripper_finger_link'>
        <pose frame=''>1.1281 0.015425 0.78601 0 -0 0</pose>
        <inertial>
          <pose frame=''>-0.01 0 0 0 -0 0</pose>
          <mass>0.0798</mass>
          <inertia>
            <ixx>0.002</ixx>
            <ixy>0</ixy>
            <ixz>0</ixz>
            <iyy>0</iyy>
            <iyz>0</iyz>
            <izz>0</izz>
          </inertia>
        </inertial>
        <collision name='r_gripper_finger_link_collision'>
          <pose frame=''>0 0.101425 0 0 -0 0</pose>
          <geometry>
            <mesh>
              <scale>1 1 1</scale>
              <uri>/home/ozymandias/smoothiebot_ws/src/fetch_ros/fetch_description/meshes/r_gripper_finger_link.STL</uri>
            </mesh>
          </geometry>
          <surface>
            <contact>
              <ode>
                <kp>1e+06</kp>
                <kd>100</kd>
                <max_vel>1</max_vel>
                <min_depth>0.001</min_depth>
              </ode>
            </contact>
            <friction>
              <ode>
                <mu>30</mu>
                <mu2>30</mu2>
              </ode>
              <torsional>
                <ode/>
              </torsional>
            </friction>
            <bounce/>
          </surface>
          <max_contacts>10</max_contacts>
        </collision>
        <visual name='r_gripper_finger_link_visual'>
          <pose frame=''>0 0.101425 0 0 -0 0</pose>
          <geometry>
            <mesh>
              <scale>1 1 1</scale>
              <uri>/home/ozymandias/smoothiebot_ws/src/fetch_ros/fetch_description/meshes/r_gripper_finger_link.STL</uri>
            </mesh>
          </geometry>
          <material>
            <script>
              <name>Gazebo/Grey</name>
              <uri>file://media/materials/scripts/gazebo.material</uri>
            </script>
          </material>
        </visual>
        <gravity>1</gravity>
        <velocity_decay/>
        <self_collide>0</self_collide>
        <kinematic>0</kinematic>
      </link>
      <joint name='r_gripper_finger_joint' type='prismatic'>
        <child>r_gripper_finger_link</child>
        <parent>wrist_roll_link</parent>
        <axis>
          <xyz>0 1 -0</xyz>
          <limit>
            <lower>0</lower>
            <upper>0.05</upper>
            <effort>60</effort>
            <velocity>0.05</velocity>
          </limit>
          <dynamics>
            <damping>100</damping>
            <friction>0</friction>
            <spring_reference>0</spring_reference>
            <spring_stiffness>0</spring_stiffness>
          </dynamics>
          <use_parent_model_frame>1</use_parent_model_frame>
        </axis>
      </joint>
      <static>0</static>
      <plugin name='fetch_gazebo_plugin' filename='libfetch_gazebo_plugin.so'>
        <robotNamespace>/</robotNamespace>
      </plugin>
      <pose frame=''>0 0 0 0 -0 0</pose>
    </model>
    <model name='cafe_table'>
      <static>1</static>
      <link name='link'>
        <collision name='surface'>
          <pose frame=''>0 0 0.755 0 -0 0</pose>
          <geometry>
            <box>
              <size>0.913 0.913 0.04</size>
            </box>
          </geometry>
          <max_contacts>10</max_contacts>
          <surface>
            <contact>
              <ode/>
            </contact>
            <bounce/>
            <friction>
              <torsional>
                <ode/>
              </torsional>
              <ode/>
            </friction>
          </surface>
        </collision>
        <collision name='column'>
          <pose frame=''>0 0 0.37 0 -0 0</pose>
          <geometry>
            <box>
              <size>0.042 0.042 0.74</size>
            </box>
          </geometry>
          <max_contacts>10</max_contacts>
          <surface>
            <contact>
              <ode/>
            </contact>
            <bounce/>
            <friction>
              <torsional>
                <ode/>
              </torsional>
              <ode/>
            </friction>
          </surface>
        </collision>
        <collision name='base'>
          <pose frame=''>0 0 0.02 0 -0 0</pose>
          <geometry>
            <box>
              <size>0.56 0.56 0.04</size>
            </box>
          </geometry>
          <max_contacts>10</max_contacts>
          <surface>
            <contact>
              <ode/>
            </contact>
            <bounce/>
            <friction>
              <torsional>
                <ode/>
              </torsional>
              <ode/>
            </friction>
          </surface>
        </collision>
        <visual name='visual'>
          <geometry>
            <mesh>
              <uri>model://cafe_table/meshes/cafe_table.dae</uri>
              <scale>1 1 1</scale>
            </mesh>
          </geometry>
        </visual>
        <self_collide>0</self_collide>
        <kinematic>0</kinematic>
        <gravity>1</gravity>
      </link>
      <pose frame=''>1 0 0 0 -0 0</pose>
    </model>
    <state world_name='default'>
      <sim_time>229 262000000</sim_time>
      <real_time>993 598316483</real_time>
      <wall_time>1524151799 218438669</wall_time>
      <iterations>229262</iterations>
      <model name='cafe_table'>
        <pose frame=''>0.875145 0.018239 0 0 -0 0</pose>
        <scale>1 1 1</scale>
        <link name='link'>
          <pose frame=''>0.875145 0.018239 0 0 -0 0</pose>
          <velocity>0 0 0 0 -0 0</velocity>
          <acceleration>0 0 0 0 -0 0</acceleration>
          <wrench>0 0 0 0 -0 0</wrench>
        </link>
      </model>
      <model name='coke_can'>
        <pose frame=''>0.809702 -0.200531 0.770862 -0.042211 0.015161 -0.000758</pose>
        <scale>1 1 1</scale>
        <link name='link'>
          <pose frame=''>0.809702 -0.200531 0.770862 -0.042211 0.015161 -0.000758</pose>
          <velocity>0 0 0 0 -0 0</velocity>
          <acceleration>0 0 0 0 -0 0</acceleration>
          <wrench>0 0 0 0 -0 0</wrench>
        </link>
      </model>
      <model name='fetch'>
        <pose frame=''>-0.09403 -0.031929 0.000598 -4e-06 -0.002844 -1.51238</pose>
        <scale>1 1 1</scale>
        <link name='base_link'>
          <pose frame=''>-0.09403 -0.031929 0.000598 -4e-06 -0.002844 -1.51238</pose>
          <velocity>0.000414 -9.8e-05 -0.0007 0.001859 -0.001768 0.002628</velocity>
          <acceleration>-0.04142 -0.125556 -0.124804 0.467062 0.893998 -1.20192</acceleration>
          <wrench>-3.45513 -10.4735 -10.4108 0 -0 0</wrench>
        </link>
        <link name='bellows_link'>
          <pose frame=''>-0.099162 0.05585 0.371045 -4e-06 -0.002843 -1.51238</pose>
          <velocity>-0.000566 -0.000807 3.9e-05 0.001723 -0.001918 0.002044</velocity>
          <acceleration>-0.382834 -0.182454 -0.016491 2.79542 -0.144701 -2.30322</acceleration>
          <wrench>-0.064842 -0.030903 -0.002793 0 -0 0</wrench>
        </link>
        <link name='elbow_flex_link'>
          <pose frame=''>0.08138 -0.097083 0.439945 -3.10498 0.018472 -3.13616</pose>
          <velocity>-0.000278 0.000632 -0.000587 0.003655 0.000559 0.001283</velocity>
          <acceleration>-0.150018 -0.210595 -0.192523 -0.46089 -1.27608 -1.87851</acceleration>
          <wrench>-0.319523 -0.448546 -0.410054 0 -0 0</wrench>
        </link>
        <link name='forearm_roll_link'>
          <pose frame=''>-0.115584 -0.098154 0.436307 -3.105 0.018472 -3.13616</pose>
          <velocity>-0.000279 0.000377 -0.000489 0.000255 0.000498 0.001278</velocity>
          <acceleration>-0.192291 -0.034837 -0.299523 2.9978 -1.07034 -1.93195</acceleration>
          <wrench>-0.318492 -0.0577 -0.4961 0 -0 0</wrench>
        </link>
        <link name='head_pan_link'>
          <pose frame=''>-0.096159 0.004547 0.980929 -5e-06 -0.002843 -1.51191</pose>
          <velocity>-0.001163 -0.001811 -0.000631 0.001466 -0.001107 0.007748</velocity>
          <acceleration>0.251923 0.329823 -0.100834 2.27663 0.177513 -2.1376</acceleration>
          <wrench>0.568238 0.743948 -0.227441 0 -0 0</wrench>
        </link>
        <link name='head_tilt_link'>
          <pose frame=''>-0.08778 -0.137571 1.03933 -5e-06 0.001015 -1.51191</pose>
          <velocity>-0.000125 -0.001854 -0.000851 -0.013302 -0.001961 0.007866</velocity>
          <acceleration>0.064973 0.307496 -0.039696 1.92547 0.830944 0.618397</acceleration>
          <wrench>0.059041 0.279422 -0.036071 0 -0 0</wrench>
        </link>
        <link name='l_gripper_finger_link'>
          <pose frame=''>-0.218245 -0.15282 0.740378 -0.477839 -1.49116 0.481323</pose>
          <velocity>-0.000873 0.168305 -0.006574 -0.000537 0.000393 0.000779</velocity>
          <acceleration>-1.66428 335.427 -12.625 -2.60502 -0.995292 -3.08859</acceleration>
          <wrench>-0.13281 26.7671 -1.00748 0 -0 0</wrench>
        </link>
        <link name='l_wheel_link'>
          <pose frame=''>0.093097 -0.022121 0.055925 3.14159 -1.09012 1.62921</pose>
          <velocity>0.000161 0.000324 -0.000324 -0.003945 0.004982 0.001872</velocity>
          <acceleration>0.003993 0.764685 -0.131009 -1.91361 1.53054 0.665787</acceleration>
          <wrench>0.017388 3.32959 -0.570438 0 -0 0</wrench>
        </link>
        <link name='r_gripper_finger_link'>
          <pose frame=''>-0.218868 -0.022353 0.735602 -0.477829 -1.49116 0.481312</pose>
          <velocity>0.0007 -0.167033 0.005572 -0.001467 0.000456 -0.00029</velocity>
          <acceleration>0 0 0 0 -0 0</acceleration>
          <wrench>0.122942 -26.7535 0.951632 0 -0 0</wrench>
        </link>
        <link name='r_wheel_link'>
          <pose frame=''>-0.281023 -0.044 0.055927 2.1e-05 0.451058 -1.51238</pose>
          <velocity>0.000363 -0.000814 -0.000555 0.008448 -0.002074 0.003429</velocity>
          <acceleration>0.01425 -1.00574 0.153606 1.53393 1.09199 -0.53216</acceleration>
          <wrench>0.062046 -4.3792 0.668829 0 -0 0</wrench>
        </link>
        <link name='shoulder_lift_link'>
          <pose frame=''>0.022591 -0.084661 0.786779 -0.016115 1.39925 -0.208254</pose>
          <velocity>-0.000558 -0.000706 -0.000633 0.002453 -0.001275 0.006496</velocity>
          <acceleration>0.345698 -0.228436 -0.149063 2.04965 0.767195 -1.75968</acceleration>
          <wrench>0.920076 -0.607982 -0.396731 0 -0 0</wrench>
        </link>
        <link name='shoulder_pan_link'>
          <pose frame=''>-0.092241 -0.062463 0.726697 -0.002758 -0.000702 -0.192373</pose>
          <velocity>-0.000724 -0.001446 -0.000804 0.001718 -0.001081 0.007124</velocity>
          <acceleration>0.33157 -0.025411 -0.213484 1.89793 1.28529 1.9875</acceleration>
          <wrench>0.848387 -0.065019 -0.546241 0 -0 0</wrench>
        </link>
        <link name='torso_lift_link'>
          <pose frame=''>-0.099163 0.055869 0.377779 -4e-06 -0.002844 -1.51238</pose>
          <velocity>-0.000562 -0.000807 -0.000586 0.0018 -0.001491 0.001842</velocity>
          <acceleration>-0.301724 0.059699 -0.187415 -0.401494 0.419985 -2.53677</acceleration>
          <wrench>-3.30357 0.653646 -2.052 0 -0 0</wrench>
        </link>
        <link name='upperarm_roll_link'>
          <pose frame=''>0.059167 -0.092389 0.570993 -0.216078 1.39925 -0.208245</pose>
          <velocity>-0.000346 0.000131 -0.000592 0.003557 -0.000555 0.001327</velocity>
          <acceleration>-0.106657 -0.333513 -0.174668 -0.831578 -0.201474 -2.18906</acceleration>
          <wrench>-0.248628 -0.777452 -0.40717 0 -0 0</wrench>
        </link>
        <link name='wrist_flex_link'>
          <pose frame=''>-0.240061 -0.09883 0.434007 -0.477792 -1.49116 0.481254</pose>
          <velocity>-0.000279 0.000219 -0.000427 0.000294 0.00065 0.001297</velocity>
          <acceleration>-0.118586 -0.182438 -0.253103 1.50344 -0.732812 -2.19097</acceleration>
          <wrench>-0.20456 -0.314706 -0.436604 0 -0 0</wrench>
        </link>
        <link name='wrist_roll_link'>
          <pose frame=''>-0.230294 -0.093729 0.572068 -0.477771 -1.49116 0.481255</pose>
          <velocity>-0.000205 0.000202 -0.000432 0.000271 0.000629 0.00104</velocity>
          <acceleration>-0.061279 -0.39785 -0.252299 -1.09669 0.749313 -2.02386</acceleration>
          <wrench>-0.101289 -0.657607 -0.417025 0 -0 0</wrench>
        </link>
      </model>
      <model name='ground_plane'>
        <pose frame=''>0 0 0 0 -0 0</pose>
        <scale>1 1 1</scale>
        <link name='link'>
          <pose frame=''>0 0 0 0 -0 0</pose>
          <velocity>0 0 0 0 -0 0</velocity>
          <acceleration>0 0 0 0 -0 0</acceleration>
          <wrench>0 0 0 0 -0 0</wrench>
        </link>
      </model>
      <model name='hammer'>
        <pose frame=''>1.04438 -0.231499 0.887755 0 -0 0</pose>
        <scale>1 1 1</scale>
        <link name='link'>
          <pose frame=''>1.04438 -0.231499 0.887755 0 -0 0</pose>
          <velocity>0 0 0 0 -0 0</velocity>
          <acceleration>0 0 0 0 -0 0</acceleration>
          <wrench>0 0 0 0 -0 0</wrench>
        </link>
      </model>
      <light name='sun'>
        <pose frame=''>0 0 10 0 -0 0</pose>
      </light>
    </state>
    <gui fullscreen='0'>
      <camera name='user_camera'>
        <pose frame=''>1.25154 -0.554163 1.12246 0 0.778204 2.64819</pose>
        <view_controller>orbit</view_controller>
        <projection_type>perspective</projection_type>
      </camera>
    </gui>
    <model name='coke_can'>
      <link name='link'>
        <inertial>
          <mass>0.39</mass>
          <inertia>
            <ixx>0.00058</ixx>
            <ixy>0</ixy>
            <ixz>0</ixz>
            <iyy>0.00058</iyy>
            <iyz>0</iyz>
            <izz>0.00019</izz>
          </inertia>
        </inertial>
        <collision name='collision'>
          <pose frame=''>0 0 -0.46 0 -0 0</pose>
          <geometry>
            <mesh>
              <uri>model://coke_can/meshes/coke_can.dae</uri>
              <scale>1 1 1</scale>
            </mesh>
          </geometry>
          <max_contacts>10</max_contacts>
          <surface>
            <contact>
              <ode/>
            </contact>
            <bounce/>
            <friction>
              <torsional>
                <ode/>
              </torsional>
              <ode/>
            </friction>
          </surface>
        </collision>
        <visual name='visual'>
          <pose frame=''>0 0 -0.46 0 -0 0</pose>
          <geometry>
            <mesh>
              <uri>model://coke_can/meshes/coke_can.dae</uri>
              <scale>1 1 1</scale>
            </mesh>
          </geometry>
        </visual>
        <self_collide>0</self_collide>
        <kinematic>0</kinematic>
        <gravity>1</gravity>
      </link>
      <pose frame=''>1.70549 -0.200403 0 0 -0 0</pose>
    </model>
    <model name='hammer'>
      <static>1</static>
      <link name='link'>
        <collision name='collision'>
          <geometry>
            <mesh>
              <uri>model://hammer/meshes/hammer.dae</uri>
              <scale>1 1 1</scale>
            </mesh>
          </geometry>
          <max_contacts>10</max_contacts>
          <surface>
            <contact>
              <ode/>
            </contact>
            <bounce/>
            <friction>
              <torsional>
                <ode/>
              </torsional>
              <ode/>
            </friction>
          </surface>
        </collision>
        <visual name='visual'>
          <geometry>
            <mesh>
              <uri>model://hammer/meshes/hammer.dae</uri>
              <scale>1 1 1</scale>
            </mesh>
          </geometry>
        </visual>
        <self_collide>0</self_collide>
        <kinematic>0</kinematic>
        <gravity>1</gravity>
      </link>
      <pose frame=''>1.80203 0.321676 0 0 -0 0</pose>
    </model>
  </world>
</sdf>
